Traceback (most recent call last):
  File "c:\program files\python 3.5\lib\runpy.py", line 184, in _run_module_as_main
    "__main__", mod_spec)
  File "c:\program files\python 3.5\lib\runpy.py", line 85, in _run_code
    exec(code, run_globals)
  File "C:\Program Files\Python 3.5\Scripts\invoke.exe\__main__.py", line 9, in <module>
  File "c:\program files\python 3.5\lib\site-packages\invoke\program.py", line 270, in run
    self.execute()
  File "c:\program files\python 3.5\lib\site-packages\invoke\program.py", line 381, in execute
    executor.execute(*self.tasks)
  File "c:\program files\python 3.5\lib\site-packages\invoke\executor.py", line 113, in execute
    result = call.task(*args, **call.kwargs)
  File "c:\program files\python 3.5\lib\site-packages\invoke\tasks.py", line 111, in __call__
    result = self.body(*args, **kwargs)
  File "S:\Documents\GitHub\blog.minchin.ca-pelican\tasks.py", line 106, in test
    ctx.run('dir')
  File "c:\program files\python 3.5\lib\site-packages\invoke\context.py", line 53, in run
    return runner_class(context=self).run(command, **kwargs)
  File "c:\program files\python 3.5\lib\site-packages\invoke\runners.py", line 259, in run
    self.start(command, shell, env)
  File "c:\program files\python 3.5\lib\site-packages\invoke\runners.py", line 966, in start
    stdin=PIPE,
  File "c:\program files\python 3.5\lib\subprocess.py", line 947, in __init__
    restore_signals, start_new_session)
  File "c:\program files\python 3.5\lib\subprocess.py", line 1224, in _execute_child
    startupinfo)
FileNotFoundError: [WinError 3] The system cannot find the path specified
